/var/spool/slurm/d/job825239/slurm_script: line 10: activate: No such file or directory
2024-11-15 18:21:50.169542: E external/local_xla/xla/stream_executor/cuda/cuda_dnn.cc:9261] Unable to register cuDNN factory: Attempting to register factory for plugin cuDNN when one has already been registered
2024-11-15 18:21:50.169596: E external/local_xla/xla/stream_executor/cuda/cuda_fft.cc:607] Unable to register cuFFT factory: Attempting to register factory for plugin cuFFT when one has already been registered
2024-11-15 18:21:50.496899: E external/local_xla/xla/stream_executor/cuda/cuda_blas.cc:1515] Unable to register cuBLAS factory: Attempting to register factory for plugin cuBLAS when one has already been registered
2024-11-15 18:21:51.315166: I tensorflow/core/platform/cpu_feature_guard.cc:182] This TensorFlow binary is optimized to use available CPU instructions in performance-critical operations.
To enable the following instructions: AVX2 FMA, in other operations, rebuild TensorFlow with the appropriate compiler flags.
Traceback (most recent call last):
  File "/home/hlaing/miniconda3/envs/teacher/lib/python3.10/site-packages/urllib3/connection.py", line 203, in _new_conn
    sock = connection.create_connection(
  File "/home/hlaing/miniconda3/envs/teacher/lib/python3.10/site-packages/urllib3/util/connection.py", line 85, in create_connection
    raise err
  File "/home/hlaing/miniconda3/envs/teacher/lib/python3.10/site-packages/urllib3/util/connection.py", line 73, in create_connection
    sock.connect(sa)
ConnectionRefusedError: [Errno 111] Connection refused

The above exception was the direct cause of the following exception:

Traceback (most recent call last):
  File "/home/hlaing/miniconda3/envs/teacher/lib/python3.10/site-packages/urllib3/connectionpool.py", line 791, in urlopen
    response = self._make_request(
  File "/home/hlaing/miniconda3/envs/teacher/lib/python3.10/site-packages/urllib3/connectionpool.py", line 497, in _make_request
    conn.request(
  File "/home/hlaing/miniconda3/envs/teacher/lib/python3.10/site-packages/urllib3/connection.py", line 395, in request
    self.endheaders()
  File "/home/hlaing/miniconda3/envs/teacher/lib/python3.10/http/client.py", line 1278, in endheaders
    self._send_output(message_body, encode_chunked=encode_chunked)
  File "/home/hlaing/miniconda3/envs/teacher/lib/python3.10/http/client.py", line 1038, in _send_output
    self.send(msg)
  File "/home/hlaing/miniconda3/envs/teacher/lib/python3.10/http/client.py", line 976, in send
    self.connect()
  File "/home/hlaing/miniconda3/envs/teacher/lib/python3.10/site-packages/urllib3/connection.py", line 243, in connect
    self.sock = self._new_conn()
  File "/home/hlaing/miniconda3/envs/teacher/lib/python3.10/site-packages/urllib3/connection.py", line 218, in _new_conn
    raise NewConnectionError(
urllib3.exceptions.NewConnectionError: <urllib3.connection.HTTPConnection object at 0x7ff73712b970>: Failed to establish a new connection: [Errno 111] Connection refused

The above exception was the direct cause of the following exception:

Traceback (most recent call last):
  File "/home/hlaing/miniconda3/envs/teacher/lib/python3.10/site-packages/requests/adapters.py", line 486, in send
    resp = conn.urlopen(
  File "/home/hlaing/miniconda3/envs/teacher/lib/python3.10/site-packages/urllib3/connectionpool.py", line 875, in urlopen
    return self.urlopen(
  File "/home/hlaing/miniconda3/envs/teacher/lib/python3.10/site-packages/urllib3/connectionpool.py", line 875, in urlopen
    return self.urlopen(
  File "/home/hlaing/miniconda3/envs/teacher/lib/python3.10/site-packages/urllib3/connectionpool.py", line 875, in urlopen
    return self.urlopen(
  [Previous line repeated 2 more times]
  File "/home/hlaing/miniconda3/envs/teacher/lib/python3.10/site-packages/urllib3/connectionpool.py", line 845, in urlopen
    retries = retries.increment(
  File "/home/hlaing/miniconda3/envs/teacher/lib/python3.10/site-packages/urllib3/util/retry.py", line 515, in increment
    raise MaxRetryError(_pool, url, reason) from reason  # type: ignore[arg-type]
urllib3.exceptions.MaxRetryError: HTTPConnectionPool(host='master.ismll.de', port=5001): Max retries exceeded with url: /api/2.0/mlflow/experiments/get-by-name?experiment_name=sim_learning_rate_0_1_and_0_0_5 (Caused by NewConnectionError('<urllib3.connection.HTTPConnection object at 0x7ff73712b970>: Failed to establish a new connection: [Errno 111] Connection refused'))

During handling of the above exception, another exception occurred:

Traceback (most recent call last):
  File "/home/hlaing/miniconda3/envs/teacher/lib/python3.10/site-packages/mlflow/utils/rest_utils.py", line 128, in http_request
    return _get_http_response_with_retries(
  File "/home/hlaing/miniconda3/envs/teacher/lib/python3.10/site-packages/mlflow/utils/request_utils.py", line 228, in _get_http_response_with_retries
    return session.request(method, url, allow_redirects=allow_redirects, **kwargs)
  File "/home/hlaing/miniconda3/envs/teacher/lib/python3.10/site-packages/requests/sessions.py", line 589, in request
    resp = self.send(prep, **send_kwargs)
  File "/home/hlaing/miniconda3/envs/teacher/lib/python3.10/site-packages/requests/sessions.py", line 703, in send
    r = adapter.send(request, **kwargs)
  File "/home/hlaing/miniconda3/envs/teacher/lib/python3.10/site-packages/requests/adapters.py", line 519, in send
    raise ConnectionError(e, request=request)
requests.exceptions.ConnectionError: HTTPConnectionPool(host='master.ismll.de', port=5001): Max retries exceeded with url: /api/2.0/mlflow/experiments/get-by-name?experiment_name=sim_learning_rate_0_1_and_0_0_5 (Caused by NewConnectionError('<urllib3.connection.HTTPConnection object at 0x7ff73712b970>: Failed to establish a new connection: [Errno 111] Connection refused'))

During handling of the above exception, another exception occurred:

Traceback (most recent call last):
  File "/home/hlaing/new/kd-srp/src/SimKD/train_student.py", line 604, in <module>
    main()
  File "/home/hlaing/new/kd-srp/src/SimKD/train_student.py", line 279, in main
    opt = parse_option()
  File "/home/hlaing/new/kd-srp/src/SimKD/train_student.py", line 184, in parse_option
    mlflow.set_experiment(experiment_name)
  File "/home/hlaing/miniconda3/envs/teacher/lib/python3.10/site-packages/mlflow/tracking/fluent.py", line 143, in set_experiment
    experiment = client.get_experiment_by_name(experiment_name)
  File "/home/hlaing/miniconda3/envs/teacher/lib/python3.10/site-packages/mlflow/tracking/client.py", line 545, in get_experiment_by_name
    return self._tracking_client.get_experiment_by_name(name)
  File "/home/hlaing/miniconda3/envs/teacher/lib/python3.10/site-packages/mlflow/tracking/_tracking_service/client.py", line 233, in get_experiment_by_name
    return self.store.get_experiment_by_name(name)
  File "/home/hlaing/miniconda3/envs/teacher/lib/python3.10/site-packages/mlflow/store/tracking/rest_store.py", line 323, in get_experiment_by_name
    response_proto = self._call_endpoint(GetExperimentByName, req_body)
  File "/home/hlaing/miniconda3/envs/teacher/lib/python3.10/site-packages/mlflow/store/tracking/rest_store.py", line 60, in _call_endpoint
    return call_endpoint(self.get_host_creds(), endpoint, method, json_body, response_proto)
  File "/home/hlaing/miniconda3/envs/teacher/lib/python3.10/site-packages/mlflow/utils/rest_utils.py", line 286, in call_endpoint
    response = http_request(**call_kwargs)
  File "/home/hlaing/miniconda3/envs/teacher/lib/python3.10/site-packages/mlflow/utils/rest_utils.py", line 151, in http_request
    raise MlflowException(f"API request to {url} failed with exception {e}")
mlflow.exceptions.MlflowException: API request to http://master.ismll.de:5001/api/2.0/mlflow/experiments/get-by-name failed with exception HTTPConnectionPool(host='master.ismll.de', port=5001): Max retries exceeded with url: /api/2.0/mlflow/experiments/get-by-name?experiment_name=sim_learning_rate_0_1_and_0_0_5 (Caused by NewConnectionError('<urllib3.connection.HTTPConnection object at 0x7ff73712b970>: Failed to establish a new connection: [Errno 111] Connection refused'))
srun: error: test-000: task 0: Exited with exit code 1
